Traceback (most recent call last):
  File "/opt/anaconda3/envs/pythonbook/lib/python3.9/site-packages/jupyter_cache/executors/utils.py", line 51, in single_nb_execution
    executenb(
  File "/opt/anaconda3/envs/pythonbook/lib/python3.9/site-packages/nbclient/client.py", line 1112, in execute
    return NotebookClient(nb=nb, resources=resources, km=km, **kwargs).execute()
  File "/opt/anaconda3/envs/pythonbook/lib/python3.9/site-packages/nbclient/util.py", line 74, in wrapped
    return just_run(coro(*args, **kwargs))
  File "/opt/anaconda3/envs/pythonbook/lib/python3.9/site-packages/nbclient/util.py", line 53, in just_run
    return loop.run_until_complete(coro)
  File "/opt/anaconda3/envs/pythonbook/lib/python3.9/asyncio/base_events.py", line 642, in run_until_complete
    return future.result()
  File "/opt/anaconda3/envs/pythonbook/lib/python3.9/site-packages/nbclient/client.py", line 553, in async_execute
    await self.async_execute_cell(
  File "/opt/anaconda3/envs/pythonbook/lib/python3.9/site-packages/nbclient/client.py", line 857, in async_execute_cell
    self._check_raise_for_error(cell, exec_reply)
  File "/opt/anaconda3/envs/pythonbook/lib/python3.9/site-packages/nbclient/client.py", line 760, in _check_raise_for_error
    raise CellExecutionError.from_cell_and_msg(cell, exec_reply_content)
nbclient.exceptions.CellExecutionError: An error occurred while executing the following cell:
------------------
%matplotlib inline
from myst_nb import glue
import numpy as np
import scipy.stats as stats
import seaborn as sns

fig, axes = plt.subplots(1, 2, figsize=(15, 5), sharey=False)

mu = 0
variance = 1
sigma = np.sqrt(variance)
x = np.linspace(mu - 3*sigma, mu + 3*sigma, 100)
sns.lineplot(x = x, y = stats.norm.pdf(x, mu, sigma), ax=axes[0])
sns.lineplot(x = x, y = stats.norm.pdf(x, mu, sigma), ax=axes[1])
plt.xlabel('Observed Value')
plt.ylabel('Probability Density')

x_fill1 = np.arange(-1, 1, 0.001)
x_fill2 = np.arange(-2, 2, 0.001)
y_fill1 = stats.norm.pdf(x_fill1,0,1)
y_fill2 = stats.norm.pdf(x_fill2,0,1)
axes[0].fill_between(x_fill1,y_fill,0, alpha=0.2, color='blue')
axes[1].fill_between(x_fill2,y_fill,0, alpha=0.2, color='blue')


sns.despine()
------------------

[0;31m---------------------------------------------------------------------------[0m
[0;31mNameError[0m                                 Traceback (most recent call last)
[0;32m<ipython-input-9-e30f90a78005>[0m in [0;36m<module>[0;34m[0m
[1;32m     20[0m [0my_fill1[0m [0;34m=[0m [0mstats[0m[0;34m.[0m[0mnorm[0m[0;34m.[0m[0mpdf[0m[0;34m([0m[0mx_fill1[0m[0;34m,[0m[0;36m0[0m[0;34m,[0m[0;36m1[0m[0;34m)[0m[0;34m[0m[0;34m[0m[0m
[1;32m     21[0m [0my_fill2[0m [0;34m=[0m [0mstats[0m[0;34m.[0m[0mnorm[0m[0;34m.[0m[0mpdf[0m[0;34m([0m[0mx_fill2[0m[0;34m,[0m[0;36m0[0m[0;34m,[0m[0;36m1[0m[0;34m)[0m[0;34m[0m[0;34m[0m[0m
[0;32m---> 22[0;31m [0maxes[0m[0;34m[[0m[0;36m0[0m[0;34m][0m[0;34m.[0m[0mfill_between[0m[0;34m([0m[0mx_fill1[0m[0;34m,[0m[0my_fill[0m[0;34m,[0m[0;36m0[0m[0;34m,[0m [0malpha[0m[0;34m=[0m[0;36m0.2[0m[0;34m,[0m [0mcolor[0m[0;34m=[0m[0;34m'blue'[0m[0;34m)[0m[0;34m[0m[0;34m[0m[0m
[0m[1;32m     23[0m [0maxes[0m[0;34m[[0m[0;36m1[0m[0;34m][0m[0;34m.[0m[0mfill_between[0m[0;34m([0m[0mx_fill2[0m[0;34m,[0m[0my_fill[0m[0;34m,[0m[0;36m0[0m[0;34m,[0m [0malpha[0m[0;34m=[0m[0;36m0.2[0m[0;34m,[0m [0mcolor[0m[0;34m=[0m[0;34m'blue'[0m[0;34m)[0m[0;34m[0m[0;34m[0m[0m
[1;32m     24[0m [0;34m[0m[0m

[0;31mNameError[0m: name 'y_fill' is not defined
NameError: name 'y_fill' is not defined

