Traceback (most recent call last):
  File "/opt/anaconda3/envs/pythonbook/lib/python3.9/site-packages/jupyter_cache/executors/utils.py", line 51, in single_nb_execution
    executenb(
  File "/opt/anaconda3/envs/pythonbook/lib/python3.9/site-packages/nbclient/client.py", line 1112, in execute
    return NotebookClient(nb=nb, resources=resources, km=km, **kwargs).execute()
  File "/opt/anaconda3/envs/pythonbook/lib/python3.9/site-packages/nbclient/util.py", line 74, in wrapped
    return just_run(coro(*args, **kwargs))
  File "/opt/anaconda3/envs/pythonbook/lib/python3.9/site-packages/nbclient/util.py", line 53, in just_run
    return loop.run_until_complete(coro)
  File "/opt/anaconda3/envs/pythonbook/lib/python3.9/asyncio/base_events.py", line 642, in run_until_complete
    return future.result()
  File "/opt/anaconda3/envs/pythonbook/lib/python3.9/site-packages/nbclient/client.py", line 553, in async_execute
    await self.async_execute_cell(
  File "/opt/anaconda3/envs/pythonbook/lib/python3.9/site-packages/nbclient/client.py", line 857, in async_execute_cell
    self._check_raise_for_error(cell, exec_reply)
  File "/opt/anaconda3/envs/pythonbook/lib/python3.9/site-packages/nbclient/client.py", line 760, in _check_raise_for_error
    raise CellExecutionError.from_cell_and_msg(cell, exec_reply_content)
nbclient.exceptions.CellExecutionError: An error occurred while executing the following cell:
------------------
ttest_1samp(a = grades, popmean = 67.5)

#from scipy.stats import ttest_1samp
#from scipy.stats import t
#from scipy.stats import sem

#confidence_level = 0.95
#degrees_freedom = len(grades)-1
#sample_mean = statistics.mean(grades)
#sample_standard_error = sem(grades)

#confidence_interval = t.interval(confidence_level, degrees_freedom, sample_mean, sample_standard_error)
#confidence_interval
------------------

[0;31m---------------------------------------------------------------------------[0m
[0;31mNameError[0m                                 Traceback (most recent call last)
[0;32m<ipython-input-16-24159f7b86d4>[0m in [0;36m<module>[0;34m[0m
[0;32m----> 1[0;31m [0mttest_1samp[0m[0;34m([0m[0ma[0m [0;34m=[0m [0mgrades[0m[0;34m,[0m [0mpopmean[0m [0;34m=[0m [0;36m67.5[0m[0;34m)[0m[0;34m[0m[0;34m[0m[0m
[0m[1;32m      2[0m [0;34m[0m[0m
[1;32m      3[0m [0;31m#from scipy.stats import ttest_1samp[0m[0;34m[0m[0;34m[0m[0;34m[0m[0m
[1;32m      4[0m [0;31m#from scipy.stats import t[0m[0;34m[0m[0;34m[0m[0;34m[0m[0m
[1;32m      5[0m [0;31m#from scipy.stats import sem[0m[0;34m[0m[0;34m[0m[0;34m[0m[0m

[0;31mNameError[0m: name 'ttest_1samp' is not defined
NameError: name 'ttest_1samp' is not defined

