Traceback (most recent call last):
  File "/opt/anaconda3/envs/pythonbook/lib/python3.9/site-packages/jupyter_cache/executors/utils.py", line 51, in single_nb_execution
    executenb(
  File "/opt/anaconda3/envs/pythonbook/lib/python3.9/site-packages/nbclient/client.py", line 1112, in execute
    return NotebookClient(nb=nb, resources=resources, km=km, **kwargs).execute()
  File "/opt/anaconda3/envs/pythonbook/lib/python3.9/site-packages/nbclient/util.py", line 74, in wrapped
    return just_run(coro(*args, **kwargs))
  File "/opt/anaconda3/envs/pythonbook/lib/python3.9/site-packages/nbclient/util.py", line 53, in just_run
    return loop.run_until_complete(coro)
  File "/opt/anaconda3/envs/pythonbook/lib/python3.9/asyncio/base_events.py", line 642, in run_until_complete
    return future.result()
  File "/opt/anaconda3/envs/pythonbook/lib/python3.9/site-packages/nbclient/client.py", line 553, in async_execute
    await self.async_execute_cell(
  File "/opt/anaconda3/envs/pythonbook/lib/python3.9/site-packages/nbclient/client.py", line 857, in async_execute_cell
    self._check_raise_for_error(cell, exec_reply)
  File "/opt/anaconda3/envs/pythonbook/lib/python3.9/site-packages/nbclient/client.py", line 760, in _check_raise_for_error
    raise CellExecutionError.from_cell_and_msg(cell, exec_reply_content)
nbclient.exceptions.CellExecutionError: An error occurred while executing the following cell:
------------------
from myst_nb import glue
import numpy as np
from scipy.stats import binom
import seaborn as sns
theta = numpy.arange(0.01,.99,0.01)
#data = random.binomial(n=100, p=.5, size=10000)
n = 100 

prob = []
for k in theta:
    prob.append(binom.cdf(40,n, k) + 1 - binom.cdf(59,n, k))


#sns.lineplot(theta, prob_lower)
ax = sns.lineplot(x = theta, y = prob)
ax.set_title("Power Function for the Test (N=100)")
ax.set(xlabel='True value of $\\theta$', ylabel='Probablility of rejecting the Null')


glue("powerfunction_fig", ax, display=False)
------------------

[0;31m---------------------------------------------------------------------------[0m
[0;31mNameError[0m                                 Traceback (most recent call last)
[0;32m<ipython-input-7-f50fea121ed3>[0m in [0;36m<module>[0;34m[0m
[1;32m      3[0m [0;32mfrom[0m [0mscipy[0m[0;34m.[0m[0mstats[0m [0;32mimport[0m [0mbinom[0m[0;34m[0m[0;34m[0m[0m
[1;32m      4[0m [0;32mimport[0m [0mseaborn[0m [0;32mas[0m [0msns[0m[0;34m[0m[0;34m[0m[0m
[0;32m----> 5[0;31m [0mtheta[0m [0;34m=[0m [0mnumpy[0m[0;34m.[0m[0marange[0m[0;34m([0m[0;36m0.01[0m[0;34m,[0m[0;36m.99[0m[0;34m,[0m[0;36m0.01[0m[0;34m)[0m[0;34m[0m[0;34m[0m[0m
[0m[1;32m      6[0m [0;31m#data = random.binomial(n=100, p=.5, size=10000)[0m[0;34m[0m[0;34m[0m[0;34m[0m[0m
[1;32m      7[0m [0mn[0m [0;34m=[0m [0;36m100[0m[0;34m[0m[0;34m[0m[0m

[0;31mNameError[0m: name 'numpy' is not defined
NameError: name 'numpy' is not defined

